Workbook
Name NativeTimeline_Order_Date: #N/A
Name Slicer_Product_Category: #N/A
Name Slicer_Region: #N/A

Sheet DASHBOARD
F2: Sales Performance Dashboard
J13: =SUM(Dataset!E:E) -> 195217.76 | Q13: =SUM(Dataset!I:I) -> 68287.01 | X13: =COUNTA(Dataset!A2:A201) -> 200 | AE13: =AVERAGE(Dataset!G:G) -> 0.09725
J18: Total Sales | Q18: Total Profit | X18: Total Orders | AE18: Avg Discount %

Sheet Dataset
A1: Customer_ID | B1: Customer_Name | C1: Region | D1: Product_Category | E1: Sales | F1: Quantity | G1: Discount | H1: Order_Date | I1: Profit
A2: CUST019 | B2: James Davis | C2: West | D2: Books | E2: 1036.09 | F2: 4 | G2: 0.2 | H2: 45392 | I2: 331.55
A3: CUST012 | B3: Robert Anderson | C3: West | D3: Clothing | E3: 1101.28 | F3: 3 | G3: 0.2 | H3: 45393 | I3: 440.51
A4: CUST017 | B4: James Taylor | C4: East | D4: Books | E4: 713.34 | F4: 17 | G4: 0 | H4: 45396 | I4: 285.34
A5: CUST005 | B5: Robert Anderson | C5: South | D5: Electronics | E5: 760.93 | F5: 4 | G5: 0.15 | H5: 45396 | I5: 161.7
A6: CUST030 | B6: James Wilson | C6: North | D6: Books | E6: 847 | F6: 12 | G6: 0.2 | H6: 45397 | I6: 271.04
A7: CUST007 | B7: Michael Anderson | C7: North | D7: Furniture | E7: 965.64 | F7: 8 | G7: 0.1 | H7: 45398 | I7: 304.18
A8: CUST001 | B8: Linda Wilson | C8: West | D8: Electronics | E8: 1317.53 | F8: 12 | G8: 0.05 | H8: 45398 | I8: 312.91
A9: CUST026 | B9: Mary Davis | C9: East | D9: Furniture | E9: 1074.47 | F9: 6 | G9: 0.2 | H9: 45401 | I9: 300.85
A10: CUST009 | B10: Linda Jackson | C10: Central | D10: Books | E10: 501.54 | F10: 11 | G10: 0.05 | H10: 45401 | I10: 190.59
A11: CUST010 | B11: David Thomas | C11: Central | D11: Clothing | E11: 737.31 | F11: 2 | G11: 0.05 | H11: 45401 | I11: 350.22
A12: CUST014 | B12: Emma Davis | C12: West | D12: Office Supplies | E12: 1572.82 | F12: 6 | G12: 0.05 | H12: 45402 | I12: 672.38
A13: CUST014 | B13: David Thomas | C13: Central | D13: Books | E13: 1343.13 | F13: 14 | G13: 0.15 | H13: 45404 | I13: 456.66
... A201: CUST016 | B201: David Thomas | C201: South | D201: Clothing | E201: 928.32 | F201: 2 | G201: 0.05 | H201: 45754 | I201: 440.95

Sheet Task_1
A1: Customer_ID | B1: Customer_Name | C1: Sales
A2: CUST015 | B2: James Wilson | C2: 1923.66
A3: CUST015 | B3: James Wilson | C3: 1681.21
A4: CUST024 | B4: Linda Taylor | C4: 1622.62
A5: CUST002 | B5: Mary Jackson | C5: 1618.22
A6: CUST004 | B6: Mary Davis | C6: 1589.42
A7: CUST014 | B7: Emma Davis | C7: 1572.82
A8: CUST024 | B8: Emma Davis | C8: 1526.6
A9: CUST006 | B9: Mary Jackson | C9: 1506.14
A10: CUST005 | B10: Sarah Anderson | C10: 1502.93
A11: CUST007 | B11: David Brown | C11: 1493.49
A12: CUST027 | B12: Linda Wilson | C12: 1488.58
A13: CUST024 | B13: David Thomas | C13: 1465.35
... A201: CUST027 | B201: James Wilson | C201: 258.51

Sheet Task_2
A1: Total Sales | B1: =SUMIF(Dataset!E:E,">0",Dataset!E:E) -> 195217.76 | D1: Discount % | E1: Expected Profit
A2: Total Profit | B2: =SUMIF(Dataset!I:I,">0",Dataset!I:I) -> 68287.01 | D2: 0 | E2: {=SUMPRODUCT(Dataset!E$2:E$201*(1-D2)*0.35)} -> 68326.216
A3: Current Avg Discount | B3: =AVERAGE(Dataset!G:G) -> 0.09725 | D3: 0.05 | E3: {=SUMPRODUCT(Dataset!E$2:E$201*(1-D3)*0.35)} -> 64909.905
D4: 0.1 | E4: {=SUMPRODUCT(Dataset!E$2:E$201*(1-D4)*0.35)} -> 61493.594
A5: New Discount % | B5: 10 | D5: 0.15 | E5: {=SUMPRODUCT(Dataset!E$2:E$201*(1-D5)*0.35)} -> 58077.284
A6: New Total Profit | B6: {=SUMPRODUCT(Dataset!E$2:E$201*(1-(B5/100))*0.35)} -> 61493.594 | D6: 0.2 | E6: {=SUMPRODUCT(Dataset!E$2:E$201*(1-D6)*0.35)} -> 54660.973
A7: Profit Change | B7: =B6-B2 -> -6793.4156 | D7: 0.25 | E7: {=SUMPRODUCT(Dataset!E$2:E$201*(1-D7)*0.35)} -> 51244.662
A8: Impact % | B8: =B7/B2 -> -0.099483278 | D8: 0.3 | E8: {=SUMPRODUCT(Dataset!E$2:E$201*(1-D8)*0.35)} -> 47828.351

Sheet Task_3
A1: SUMMARY OUTPUT
A3: Regression Statistics
A4: Multiple R | B4: 0.97220677
A5: R Square | B5: 0.94518601
A6: Adjusted R Square | B6: 0.9401355
A7: Standard Error | B7: 86.253547
A8: Observations | B8: 199
A10: ANOVA
B11: df | C11: SS | D11: MS | E11: F | F11: Significance F
A12: Regression | B12: 1 | C12: 25400657 | D12: 25400657 | E12: 3414.2163 | F12: 2.1992016e-126
A13: Residual | B13: 198 | C13: 1473055.5 | D13: 7439.6744
A14: Total | B14: 199 | C14: 26873713
B16: Coefficients | C16: Standard Error | D16: t Stat | E16: P-value | F16: Lower 95% | G16: Upper 95% | H16: Lower 95.0% | I16: Upper 95.0%
A17: Intercept | B17: 0 | C17: #N/A | D17: #N/A | E17: #N/A | F17: #N/A | G17: #N/A | H17: #N/A | I17: #N/A
A18: 1036.09 | B18: 0.35004434 | C18: 0.0059906996 | D18: 58.431295 | E18: 8.2305322e-127 | F18: 0.33823057 | G18: 0.3618581 | H18: 0.33823057 | I18: 0.3618581
A22: RESIDUAL OUTPUT | F22: PROBABILITY OUTPUT
A24: Observation | B24: Predicted 331.55 | C24: Residuals | D24: Standard Residuals | F24: Percentile | G24: 331.55
A25: 1 | B25: 385.49683 | C25: 55.013171 | D25: 0.63941624 | F25: 0.25125628 | G25: 64.63
A26: 2 | B26: 249.70063 | C26: 35.639372 | D26: 0.41423522 | F26: 0.75376884 | G26: 82.57
A27: 3 | B27: 266.35924 | C27: -104.65924 | D27: -1.2164508 | F27: 1.2562814 | G27: 91.71
A28: 4 | B28: 296.48755 | C28: -25.447554 | D28: -0.29577607 | F28: 1.758794 | G28: 111.39
A29: 5 | B29: 338.01681 | C29: -33.836815 | D29: -0.39328416 | F29: 2.2613065 | G29: 114.7
A30: 6 | B30: 461.19392 | C30: -148.28392 | D30: -1.723499 | F30: 2.7638191 | G30: 121.54
A31: 7 | B31: 376.11214 | C31: -75.26214 | D31: -0.87476932 | F31: 3.2663317 | G31: 134.66
A32: 8 | B32: 175.56124 | C32: 15.028763 | D32: 0.1746788 | F32: 3.7688442 | G32: 144.56
A33: 9 | B33: 258.09119 | C33: 92.128809 | D33: 1.07081 | F33: 4.2713568 | G33: 148.32
A34: 10 | B34: 550.55674 | C34: 121.82326 | D34: 1.4159477 | F34: 4.7738693 | G34: 150.18
A35: 11 | B35: 470.15505 | C35: -13.495052 | D35: -0.15685254 | F35: 5.2763819 | G35: 151.16
A36: 12 | B36: 417.10583 | C36: 35.694167 | D36: 0.41487211 | F36: 5.7788945 | G36: 155.2
... A223: 199 | B223: 324.95316 | C223: 115.99684 | D223: 1.3482274 | F223: 99.748744 | G223: 769.46

Sheet Task_4
A1: Sales | D1: Quantity | G1: Discount | J1: Profit
A2: Mean | B2: 975.78729 | D2: Mean | E2: 10.025126 | G2: Mean | H2: 0.096733668 | J2: Mean | K2: 341.43505
A3: Standard Error | B3: 21.266301 | D3: Standard Error | E3: 0.40014446 | G3: Standard Error | H3: 0.0051137433 | J3: Standard Error | K3: 9.6001196
A4: Median | B4: 973.26 | D4: Median | E4: 10 | G4: Median | H4: 0.1 | J4: Median | K4: 332.255
A5: Mode | B5: #N/A | D5: Mode | E5: 8 | G5: Mode | H5: 0 | J5: Mode | K5: #N/A
A6: Standard Deviation | B6: 299.99809 | D6: Standard Deviation | E6: 5.6447322 | G6: Standard Deviation | H6: 0.072138226 | J6: Standard Deviation | K6: 135.76619
A7: Sample Variance | B7: 89998.856 | D7: Sample Variance | E7: 31.863002 | G7: Sample Variance | H7: 0.0052039237 | J7: Sample Variance | K7: 18432.459
A8: Kurtosis | B8: -0.10144708 | D8: Kurtosis | E8: -1.2052158 | G8: Kurtosis | H8: -1.3175588 | J8: Kurtosis | K8: 0.26450644
A9: Skewness | B9: 0.14954552 | D9: Skewness | E9: 0.051156001 | G9: Skewness | H9: 0.10503298 | J9: Skewness | K9: 0.57339636
A10: Range | B10: 1665.15 | D10: Range | E10: 18 | G10: Range | H10: 0.2 | J10: Range | K10: 704.83
A11: Minimum | B11: 258.51 | D11: Minimum | E11: 1 | G11: Minimum | H11: 0 | J11: Minimum | K11: 64.63
A12: Maximum | B12: 1923.66 | D12: Maximum | E12: 19 | G12: Maximum | H12: 0.2 | J12: Maximum | K12: 769.46
A13: Sum | B13: 194181.67 | D13: Sum | E13: 1995 | G13: Sum | H13: 19.25 | J13: Sum | K13: 68287.01
A14: Count | B14: 199 | D14: Count | E14: 199 | G14: Count | H14: 199 | J14: Count | K14: 200
A15: Confidence Level(95.0%) | B15: 41.937517 | D15: Confidence Level(95.0%) | E15: 0.78909186 | G15: Confidence Level(95.0%) | H15: 0.010084391 | J15: Confidence Level(95.0%) | K15: 18.931019

Sheet Task_5 
A1: Month | B1: Total Sales | C1: MoM Change | D1: Growth % | E1: Trend
A2: =MIN(Dataset!H:H) -> 45392 | B2: {=SUMPRODUCT((MONTH(Dataset!H$2:H$201)=MONTH(A2))*(YEAR(Dataset!H$2:H$201)=YEAR(A2))*Dataset!E$2:E$201)} -> 19029.96 | C2: =IF(ROW()=2,"—",B2-B1) -> — | D2: =IF(ROW()=2,"—",(B2-B1)/B1) -> — | E2: =F9=IF(C2="—","—",IF(C2>0,"▲","▼")) -> FALSE
A3: =EDATE(A2,1) -> 45422 | B3: {=SUMPRODUCT((MONTH(Dataset!H$2:H$201)=MONTH(A3))*(YEAR(Dataset!H$2:H$201)=YEAR(A3))*Dataset!E$2:E$201)} -> 18507.34 | C3: =IF(ROW()=2,"—",B3-B2) -> -522.62 | D3: =IF(ROW()=2,"—",(B3-B2)/B2) -> -0.027463011 | E3: =IF(C3="—","—",IF(C3>0,"▲","▼")) -> ▼
A4: =EDATE(A2,2) -> 45453 | B4: {=SUMPRODUCT((MONTH(Dataset!H$2:H$201)=MONTH(A4))*(YEAR(Dataset!H$2:H$201)=YEAR(A4))*Dataset!E$2:E$201)} -> 20187.51 | C4: =IF(ROW()=2,"—",B4-B3) -> 1680.17 | D4: =IF(ROW()=2,"—",(B4-B3)/B3) -> 0.090783981 | E4: =IF(C4="—","—",IF(C4>0,"▲","▼")) -> ▲
A5: =EDATE(A4,1) -> 45483 | B5: {=SUMPRODUCT((MONTH(Dataset!H$2:H$201)=MONTH(A5))*(YEAR(Dataset!H$2:H$201)=YEAR(A5))*Dataset!E$2:E$201)} -> 11609.04 | C5: =IF(ROW()=2,"—",B5-B4) -> -8578.47 | D5: =IF(ROW()=2,"—",(B5-B4)/B4) -> -0.42493948 | E5: =IF(C5="—","—",IF(C5>0,"▲","▼")) -> ▼
A6: =EDATE(A4,2) -> 45514 | B6: {=SUMPRODUCT((MONTH(Dataset!H$2:H$201)=MONTH(A6))*(YEAR(Dataset!H$2:H$201)=YEAR(A6))*Dataset!E$2:E$201)} -> 10091.7 | C6: =IF(ROW()=2,"—",B6-B5) -> -1517.34 | D6: =IF(ROW()=2,"—",(B6-B5)/B5) -> -0.13070331 | E6: =IF(C6="—","—",IF(C6>0,"▲","▼")) -> ▼
A7: =EDATE(A6,1) -> 45545 | B7: {=SUMPRODUCT((MONTH(Dataset!H$2:H$201)=MONTH(A7))*(YEAR(Dataset!H$2:H$201)=YEAR(A7))*Dataset!E$2:E$201)} -> 20533.5 | C7: =IF(ROW()=2,"—",B7-B6) -> 10441.8 | D7: =IF(ROW()=2,"—",(B7-B6)/B6) -> 1.0346919 | E7: =IF(C7="—","—",IF(C7>0,"▲","▼")) -> ▲
A8: =EDATE(A6,2) -> 45575 | B8: {=SUMPRODUCT((MONTH(Dataset!H$2:H$201)=MONTH(A8))*(YEAR(Dataset!H$2:H$201)=YEAR(A8))*Dataset!E$2:E$201)} -> 14215.24 | C8: =IF(ROW()=2,"—",B8-B7) -> -6318.26 | D8: =IF(ROW()=2,"—",(B8-B7)/B7) -> -0.30770497 | E8: =IF(C8="—","—",IF(C8>0,"▲","▼")) -> ▼
A9: =EDATE(A8,1) -> 45606 | B9: {=SUMPRODUCT((MONTH(Dataset!H$2:H$201)=MONTH(A9))*(YEAR(Dataset!H$2:H$201)=YEAR(A9))*Dataset!E$2:E$201)} -> 20135.03 | C9: =IF(ROW()=2,"—",B9-B8) -> 5919.79 | D9: =IF(ROW()=2,"—",(B9-B8)/B8) -> 0.41643968 | E9: =IF(C9="—","—",IF(C9>0,"▲","▼")) -> ▲
A10: =EDATE(A8,2) -> 45636 | B10: {=SUMPRODUCT((MONTH(Dataset!H$2:H$201)=MONTH(A10))*(YEAR(Dataset!H$2:H$201)=YEAR(A10))*Dataset!E$2:E$201)} -> 11120.04 | C10: =IF(ROW()=2,"—",B10-B9) -> -9014.99 | D10: =IF(ROW()=2,"—",(B10-B9)/B9) -> -0.44772667 | E10: =IF(C10="—","—",IF(C10>0,"▲","▼")) -> ▼
A11: =EDATE(A10,1) -> 45667 | B11: {=SUMPRODUCT((MONTH(Dataset!H$2:H$201)=MONTH(A11))*(YEAR(Dataset!H$2:H$201)=YEAR(A11))*Dataset!E$2:E$201)} -> 14914.65 | C11: =IF(ROW()=2,"—",B11-B10) -> 3794.61 | D11: =IF(ROW()=2,"—",(B11-B10)/B10) -> 0.34124068 | E11: =IF(C11="—","—",IF(C11>0,"▲","▼")) -> ▲
A12: =EDATE(A10,2) -> 45698 | B12: {=SUMPRODUCT((MONTH(Dataset!H$2:H$201)=MONTH(A12))*(YEAR(Dataset!H$2:H$201)=YEAR(A12))*Dataset!E$2:E$201)} -> 14006.36 | C12: =IF(ROW()=2,"—",B12-B11) -> -908.29 | D12: =IF(ROW()=2,"—",(B12-B11)/B11) -> -0.060899183 | E12: =IF(C12="—","—",IF(C12>0,"▲","▼")) -> ▼
A13: =EDATE(A12,1) -> 45726 | B13: {=SUMPRODUCT((MONTH(Dataset!H$2:H$201)=MONTH(A13))*(YEAR(Dataset!H$2:H$201)=YEAR(A13))*Dataset!E$2:E$201)} -> 17655.22 | C13: =IF(ROW()=2,"—",B13-B12) -> 3648.86 | D13: =IF(ROW()=2,"—",(B13-B12)/B12) -> 0.26051451 | E13: =IF(C13="—","—",IF(C13>0,"▲","▼")) -> ▲
A14: =EDATE(A12,2) -> 45757 | B14: {=SUMPRODUCT((MONTH(Dataset!H$2:H$201)=MONTH(A14))*(YEAR(Dataset!H$2:H$201)=YEAR(A14))*Dataset!E$2:E$201)} -> 3212.17 | C14: =IF(ROW()=2,"—",B14-B13) -> -14443.05 | D14: =IF(ROW()=2,"—",(B14-B13)/B13) -> -0.81806117 | E14: =IF(C14="—","—",IF(C14>0,"▲","▼")) -> ▼

Sheet Task_6
A1: Customer_ID | B1: Customer_Name | C1: Sales | D1: Timestamp
A2: CUST019 | B2: James Davis | C2: 1036.09 | D2: =NOW() -> 46165.923
A3: CUST012 | B3: Robert Anderson | C3: 1101.28 | D3: =NOW() -> 46165.923
A4: CUST017 | B4: James Taylor | C4: 713.34 | D4: =NOW() -> 46165.923
A5: CUST005 | B5: Robert Anderson | C5: 760.93 | D5: =NOW() -> 46165.923
A6: CUST030 | B6: James Wilson | C6: 847 | D6: =NOW() -> 46165.923
A7: CUST007 | B7: Michael Anderson | C7: 965.64 | D7: =NOW() -> 46165.923
A8: CUST001 | B8: Linda Wilson | C8: 1317.53 | D8: =NOW() -> 46165.923
A9: CUST026 | B9: Mary Davis | C9: 1074.47 | D9: =NOW() -> 46165.923
A10: CUST009 | B10: Linda Jackson | C10: 501.54 | D10: =NOW() -> 46165.923
A11: CUST010 | B11: David Thomas | C11: 737.31 | D11: =NOW() -> 46165.923
A12: CUST014 | B12: Emma Davis | C12: 1572.82 | D12: =NOW() -> 46165.923
A13: CUST014 | B13: David Thomas | C13: 1343.13 | D13: =NOW() -> 46165.923
... A201: CUST016 | B201: David Thomas | C201: 928.32 | D201: =NOW() -> 46165.923

Sheet Task_7
A1: Customer_ID | B1: Customer_Name | C1: Total Sales | D1: Status | E1: Rank
A2: {=IFERROR(INDEX(Dataset!A$2:A$201,MATCH(0,COUNTIF(A$1:A1,Dataset!A$2:A$201),0)),"")} -> CUST019 | B2: =IFERROR(INDEX(Dataset!B$2:B$201,MATCH(A2,Dataset!A$2:A$201,0)),"") -> James Davis | C2: =IFERROR(SUMIF(Dataset!A$2:A$201,A2,Dataset!E$2:E$201),"") -> 4640.11 | D2: =IF(C2>AVERAGE(C$2:C$31),"⭐ High Value","Normal") -> Normal | E2: =RANK(C2,C$2:C$31,0) -> 21
A3: {=IFERROR(INDEX(Dataset!A$2:A$201,MATCH(0,COUNTIF(A$1:A2,Dataset!A$2:A$201),0)),"")} -> CUST012 | B3: =IFERROR(INDEX(Dataset!B$2:B$201,MATCH(A3,Dataset!A$2:A$201,0)),"") -> Robert Anderson | C3: =IFERROR(SUMIF(Dataset!A$2:A$201,A3,Dataset!E$2:E$201),"") -> 8339 | D3: =IF(C3>AVERAGE(C$2:C$31),"⭐ High Value","Normal") -> ⭐ High Value | E3: =RANK(C3,C$2:C$31,0) -> 8
A4: {=IFERROR(INDEX(Dataset!A$2:A$201,MATCH(0,COUNTIF(A$1:A3,Dataset!A$2:A$201),0)),"")} -> CUST017 | B4: =IFERROR(INDEX(Dataset!B$2:B$201,MATCH(A4,Dataset!A$2:A$201,0)),"") -> James Taylor | C4: =IFERROR(SUMIF(Dataset!A$2:A$201,A4,Dataset!E$2:E$201),"") -> 3419.2 | D4: =IF(C4>AVERAGE(C$2:C$31),"⭐ High Value","Normal") -> Normal | E4: =RANK(C4,C$2:C$31,0) -> 28
A5: {=IFERROR(INDEX(Dataset!A$2:A$201,MATCH(0,COUNTIF(A$1:A4,Dataset!A$2:A$201),0)),"")} -> CUST005 | B5: =IFERROR(INDEX(Dataset!B$2:B$201,MATCH(A5,Dataset!A$2:A$201,0)),"") -> Robert Anderson | C5: =IFERROR(SUMIF(Dataset!A$2:A$201,A5,Dataset!E$2:E$201),"") -> 6666.13 | D5: =IF(C5>AVERAGE(C$2:C$31),"⭐ High Value","Normal") -> ⭐ High Value | E5: =RANK(C5,C$2:C$31,0) -> 14
A6: {=IFERROR(INDEX(Dataset!A$2:A$201,MATCH(0,COUNTIF(A$1:A5,Dataset!A$2:A$201),0)),"")} -> CUST030 | B6: =IFERROR(INDEX(Dataset!B$2:B$201,MATCH(A6,Dataset!A$2:A$201,0)),"") -> James Wilson | C6: =IFERROR(SUMIF(Dataset!A$2:A$201,A6,Dataset!E$2:E$201),"") -> 7928.71 | D6: =IF(C6>AVERAGE(C$2:C$31),"⭐ High Value","Normal") -> ⭐ High Value | E6: =RANK(C6,C$2:C$31,0) -> 9
A7: {=IFERROR(INDEX(Dataset!A$2:A$201,MATCH(0,COUNTIF(A$1:A6,Dataset!A$2:A$201),0)),"")} -> CUST007 | B7: =IFERROR(INDEX(Dataset!B$2:B$201,MATCH(A7,Dataset!A$2:A$201,0)),"") -> Michael Anderson | C7: =IFERROR(SUMIF(Dataset!A$2:A$201,A7,Dataset!E$2:E$201),"") -> 9941.88 | D7: =IF(C7>AVERAGE(C$2:C$31),"⭐ High Value","Normal") -> ⭐ High Value | E7: =RANK(C7,C$2:C$31,0) -> 3
A8: {=IFERROR(INDEX(Dataset!A$2:A$201,MATCH(0,COUNTIF(A$1:A7,Dataset!A$2:A$201),0)),"")} -> CUST001 | B8: =IFERROR(INDEX(Dataset!B$2:B$201,MATCH(A8,Dataset!A$2:A$201,0)),"") -> Linda Wilson | C8: =IFERROR(SUMIF(Dataset!A$2:A$201,A8,Dataset!E$2:E$201),"") -> 6549.55 | D8: =IF(C8>AVERAGE(C$2:C$31),"⭐ High Value","Normal") -> ⭐ High Value | E8: =RANK(C8,C$2:C$31,0) -> 15
A9: {=IFERROR(INDEX(Dataset!A$2:A$201,MATCH(0,COUNTIF(A$1:A8,Dataset!A$2:A$201),0)),"")} -> CUST026 | B9: =IFERROR(INDEX(Dataset!B$2:B$201,MATCH(A9,Dataset!A$2:A$201,0)),"") -> Mary Davis | C9: =IFERROR(SUMIF(Dataset!A$2:A$201,A9,Dataset!E$2:E$201),"") -> 9371.81 | D9: =IF(C9>AVERAGE(C$2:C$31),"⭐ High Value","Normal") -> ⭐ High Value | E9: =RANK(C9,C$2:C$31,0) -> 5
A10: {=IFERROR(INDEX(Dataset!A$2:A$201,MATCH(0,COUNTIF(A$1:A9,Dataset!A$2:A$201),0)),"")} -> CUST009 | B10: =IFERROR(INDEX(Dataset!B$2:B$201,MATCH(A10,Dataset!A$2:A$201,0)),"") -> Linda Jackson | C10: =IFERROR(SUMIF(Dataset!A$2:A$201,A10,Dataset!E$2:E$201),"") -> 6505.2 | D10: =IF(C10>AVERAGE(C$2:C$31),"⭐ High Value","Normal") -> Normal | E10: =RANK(C10,C$2:C$31,0) -> 16
A11: {=IFERROR(INDEX(Dataset!A$2:A$201,MATCH(0,COUNTIF(A$1:A10,Dataset!A$2:A$201),0)),"")} -> CUST010 | B11: =IFERROR(INDEX(Dataset!B$2:B$201,MATCH(A11,Dataset!A$2:A$201,0)),"") -> David Thomas | C11: =IFERROR(SUMIF(Dataset!A$2:A$201,A11,Dataset!E$2:E$201),"") -> 4259.22 | D11: =IF(C11>AVERAGE(C$2:C$31),"⭐ High Value","Normal") -> Normal | E11: =RANK(C11,C$2:C$31,0) -> 24
A12: {=IFERROR(INDEX(Dataset!A$2:A$201,MATCH(0,COUNTIF(A$1:A11,Dataset!A$2:A$201),0)),"")} -> CUST014 | B12: =IFERROR(INDEX(Dataset!B$2:B$201,MATCH(A12,Dataset!A$2:A$201,0)),"") -> Emma Davis | C12: =IFERROR(SUMIF(Dataset!A$2:A$201,A12,Dataset!E$2:E$201),"") -> 6729.89 | D12: =IF(C12>AVERAGE(C$2:C$31),"⭐ High Value","Normal") -> ⭐ High Value | E12: =RANK(C12,C$2:C$31,0) -> 12
A13: {=IFERROR(INDEX(Dataset!A$2:A$201,MATCH(0,COUNTIF(A$1:A12,Dataset!A$2:A$201),0)),"")} -> CUST023 | B13: =IFERROR(INDEX(Dataset!B$2:B$201,MATCH(A13,Dataset!A$2:A$201,0)),"") -> Robert Anderson | C13: =IFERROR(SUMIF(Dataset!A$2:A$201,A13,Dataset!E$2:E$201),"") -> 5913.68 | D13: =IF(C13>AVERAGE(C$2:C$31),"⭐ High Value","Normal") -> Normal | E13: =RANK(C13,C$2:C$31,0) -> 18
... A31: {=IFERROR(INDEX(Dataset!A$2:A$201,MATCH(0,COUNTIF(A$1:A30,Dataset!A$2:A$201),0)),"")} -> CUST018 | B31: =IFERROR(INDEX(Dataset!B$2:B$201,MATCH(A31,Dataset!A$2:A$201,0)),"") -> Mary Jackson | C31: =IFERROR(SUMIF(Dataset!A$2:A$201,A31,Dataset!E$2:E$201),"") -> 4951.89 | D31: =IF(C31>AVERAGE(C$2:C$31),"⭐ High Value","Normal") -> Normal | E31: =RANK(C31,C$2:C$31,0) -> 20

Sheet Task_8
A1: Region | B1: Product_Category | C1: Sum of Sales
A2: Central | C2: 43468.33
B3: Books | C3: 11297.15
B4: Clothing | C4: 12200.26
B5: Electronics | C5: 6621.24
B6: Furniture | C6: 4876.96
B7: Office Supplies | C7: 8472.72
A8: East | C8: 32441.64
B9: Books | C9: 11389.09
B10: Clothing | C10: 2401.45
B11: Electronics | C11: 2869.54
B12: Furniture | C12: 7592.34
B13: Office Supplies | C13: 8189.22
A14: North | C14: 34975.42
B15: Books | C15: 8037.01
B16: Clothing | C16: 8422.82
B17: Electronics | C17: 8191.71
B18: Furniture | C18: 6978.08
B19: Office Supplies | C19: 3345.8
A20: South | C20: 40248.79
B21: Books | C21: 9588.04
B22: Clothing | C22: 8393.63
B23: Electronics | C23: 11989.07
B24: Furniture | C24: 7982.73
B25: Office Supplies | C25: 2295.32
A26: West | C26: 44083.58
B27: Books | C27: 6691.17
B28: Clothing | C28: 10509.43
B29: Electronics | C29: 11372.44
B30: Furniture | C30: 9182.78
B31: Office Supplies | C31: 6327.76
A32: (blank)
A33: Grand Total | C33: 195217.76
A37: Years (Order_Date) | B37: Months (Order_Date) | C37: Order_Date | D37: Sum of Sales
A38: 2024 | D38: 145429.36
B39: Apr | D39: 19029.96
B40: May | D40: 18507.34
B41: Jun | D41: 20187.51
B42: Jul | D42: 11609.04
B43: Aug | D43: 10091.7
...

Sheet Task_9_kpi
A1: Region | B1: Total Sales | C1: Total Profit | E1: Month | F1: Monthly Sales | H1: Category | I1: Total Sales
A2: {=IFERROR(INDEX(Dataset!C$2:C$201,MATCH(0,COUNTIF(A$1:A1,Dataset!C$2:C$201),0)),"")} -> West | B2: =SUMIF(Dataset!C$2:C$201,A2,Dataset!E$2:E$201) -> 44083.58 | C2: =SUMIF(Dataset!C$2:C$201,A2,Dataset!I$2:I$201) -> 14985.83 | E2: =MIN(Dataset!H:H) -> 45392 | F2: {=SUMPRODUCT((MONTH(Dataset!H$2:H$201)=MONTH(E2))*(YEAR(Dataset!H$2:H$201)=YEAR(E2))*Dataset!E$2:E$201)} -> 19029.96 | H2: {=IFERROR(INDEX(Dataset!D$2:D$201,MATCH(0,COUNTIF(H$1:H1,Dataset!D$2:D$201),0)),"")} -> Books | I2: =SUMIF(Dataset!D$2:D$201,H2,Dataset!E$2:E$201) -> 47002.46
A3: {=IFERROR(INDEX(Dataset!C$2:C$201,MATCH(0,COUNTIF(A$1:A2,Dataset!C$2:C$201),0)),"")} -> East | B3: =SUMIF(Dataset!C$2:C$201,A3,Dataset!E$2:E$201) -> 32441.64 | C3: =SUMIF(Dataset!C$2:C$201,A3,Dataset!I$2:I$201) -> 11638.59 | E3: =EDATE(E2,1) -> 45422 | F3: {=SUMPRODUCT((MONTH(Dataset!H$2:H$201)=MONTH(E3))*(YEAR(Dataset!H$2:H$201)=YEAR(E3))*Dataset!E$2:E$201)} -> 18507.34 | H3: {=IFERROR(INDEX(Dataset!D$2:D$201,MATCH(0,COUNTIF(H$1:H2,Dataset!D$2:D$201),0)),"")} -> Clothing | I3: =SUMIF(Dataset!D$2:D$201,H3,Dataset!E$2:E$201) -> 41927.59
A4: {=IFERROR(INDEX(Dataset!C$2:C$201,MATCH(0,COUNTIF(A$1:A3,Dataset!C$2:C$201),0)),"")} -> South | B4: =SUMIF(Dataset!C$2:C$201,A4,Dataset!E$2:E$201) -> 40248.79 | C4: =SUMIF(Dataset!C$2:C$201,A4,Dataset!I$2:I$201) -> 13691.91 | E4: =EDATE(E2,2) -> 45453 | F4: {=SUMPRODUCT((MONTH(Dataset!H$2:H$201)=MONTH(E4))*(YEAR(Dataset!H$2:H$201)=YEAR(E4))*Dataset!E$2:E$201)} -> 20187.51 | H4: {=IFERROR(INDEX(Dataset!D$2:D$201,MATCH(0,COUNTIF(H$1:H3,Dataset!D$2:D$201),0)),"")} -> Electronics | I4: =SUMIF(Dataset!D$2:D$201,H4,Dataset!E$2:E$201) -> 41044
A5: {=IFERROR(INDEX(Dataset!C$2:C$201,MATCH(0,COUNTIF(A$1:A4,Dataset!C$2:C$201),0)),"")} -> North | B5: =SUMIF(Dataset!C$2:C$201,A5,Dataset!E$2:E$201) -> 34975.42 | C5: =SUMIF(Dataset!C$2:C$201,A5,Dataset!I$2:I$201) -> 11902.28 | E5: =EDATE(E4,1) -> 45483 | F5: {=SUMPRODUCT((MONTH(Dataset!H$2:H$201)=MONTH(E5))*(YEAR(Dataset!H$2:H$201)=YEAR(E5))*Dataset!E$2:E$201)} -> 11609.04 | H5: {=IFERROR(INDEX(Dataset!D$2:D$201,MATCH(0,COUNTIF(H$1:H4,Dataset!D$2:D$201),0)),"")} -> Furniture | I5: =SUMIF(Dataset!D$2:D$201,H5,Dataset!E$2:E$201) -> 36612.89
A6: {=IFERROR(INDEX(Dataset!C$2:C$201,MATCH(0,COUNTIF(A$1:A5,Dataset!C$2:C$201),0)),"")} -> Central | B6: =SUMIF(Dataset!C$2:C$201,A6,Dataset!E$2:E$201) -> 43468.33 | C6: =SUMIF(Dataset!C$2:C$201,A6,Dataset!I$2:I$201) -> 16068.4 | E6: =EDATE(E4,2) -> 45514 | F6: {=SUMPRODUCT((MONTH(Dataset!H$2:H$201)=MONTH(E6))*(YEAR(Dataset!H$2:H$201)=YEAR(E6))*Dataset!E$2:E$201)} -> 10091.7 | H6: {=IFERROR(INDEX(Dataset!D$2:D$201,MATCH(0,COUNTIF(H$1:H5,Dataset!D$2:D$201),0)),"")} -> Office Supplies | I6: =SUMIF(Dataset!D$2:D$201,H6,Dataset!E$2:E$201) -> 28630.82
E7: =EDATE(E6,1) -> 45545 | F7: {=SUMPRODUCT((MONTH(Dataset!H$2:H$201)=MONTH(E7))*(YEAR(Dataset!H$2:H$201)=YEAR(E7))*Dataset!E$2:E$201)} -> 20533.5
E8: =EDATE(E6,2) -> 45575 | F8: {=SUMPRODUCT((MONTH(Dataset!H$2:H$201)=MONTH(E8))*(YEAR(Dataset!H$2:H$201)=YEAR(E8))*Dataset!E$2:E$201)} -> 14215.24
E9: =EDATE(E8,1) -> 45606 | F9: {=SUMPRODUCT((MONTH(Dataset!H$2:H$201)=MONTH(E9))*(YEAR(Dataset!H$2:H$201)=YEAR(E9))*Dataset!E$2:E$201)} -> 20135.03
E10: =EDATE(E8,2) -> 45636 | F10: {=SUMPRODUCT((MONTH(Dataset!H$2:H$201)=MONTH(E10))*(YEAR(Dataset!H$2:H$201)=YEAR(E10))*Dataset!E$2:E$201)} -> 11120.04
E11: =EDATE(E10,1) -> 45667 | F11: {=SUMPRODUCT((MONTH(Dataset!H$2:H$201)=MONTH(E11))*(YEAR(Dataset!H$2:H$201)=YEAR(E11))*Dataset!E$2:E$201)} -> 14914.65
E12: =EDATE(E10,2) -> 45698 | F12: {=SUMPRODUCT((MONTH(Dataset!H$2:H$201)=MONTH(E12))*(YEAR(Dataset!H$2:H$201)=YEAR(E12))*Dataset!E$2:E$201)} -> 14006.36
E13: =EDATE(E12,1) -> 45726 | F13: {=SUMPRODUCT((MONTH(Dataset!H$2:H$201)=MONTH(E13))*(YEAR(Dataset!H$2:H$201)=YEAR(E13))*Dataset!E$2:E$201)} -> 17655.22
E14: =EDATE(E12,2) -> 45757 | F14: {=SUMPRODUCT((MONTH(Dataset!H$2:H$201)=MONTH(E14))*(YEAR(Dataset!H$2:H$201)=YEAR(E14))*Dataset!E$2:E$201)} -> 3212.17
